<mujoco model="walker2d">
  <compiler angle="degree" coordinate="local" inertiafromgeom="true"/>
  <!--
  <default>
    <joint armature="0.01" damping="5" stiffness="10" limited="true"/>
    <geom conaffinity="1" condim="3" contype="1" margin="0.001" friction="0.8 .1 .1" rgba="0.8 0.6 .4 1" solimp=".8 .8 .01" solref=".02 1"/>
  </default>
  -->
  <option integrator="RK4" iterations="50" solver="PGS" timestep="0.001"/>
  <worldbody>
    <!-- CHANGES: see hopper.xml -->
    <body name="base">
      <!--
      <joint armature="0" axis="1 0 0" damping="0" limited="false" name="ignorex" pos="0 0 0" stiffness="0" type="slide"/>
      <joint armature="0" axis="0 0 1" damping="0" limited="false" name="ignorez" pos="0 0 0" stiffness="0" type="slide"/>
      <joint armature="0" axis="0 1 0" damping="0" limited="false" name="ignorey" pos="0 0 0" stiffness="0" type="hinge"/>
      -->
      <geom fromto="0 0 0 0.8 0 0" name="base_geom" size="0.07" type="capsule" />

      <body name="leg">
        <joint axis="0 1 0"  pos="0.4 0.0 0.0" limited = "true" range="-90 90" type="hinge"/>
          <geom size="0.2 0.1 0.4" type="box"/>
        <!-- <geom fromto="0.4 0 0.0 0.4 0 0.6" name="thigh_geom" size="0.05" type="capsule" />
-->
        <!--
          <body name="neck">
          <joint axis="0 1 0" name="leg_joint" pos="0.4 0 0.6" limited = "true" range="-15 160" type="hinge"/>
          <geom fromto="0.4 0 0.6 0.4 0.0 1.2" name="leg_geom" size="0.05" type="capsule" density="1000"/>
          <inertial mass="10"/>
          <body name="head">
            <geom fromto="0.4 0 1.2 0.6 0 1.2" name="head_geom" size="0.1" type="capsule" density="2000"/>
          <inertial mass="50"/>
          </body>
        </body>
        -->
      </body>
    </body>

    <!-- copied and then replace thigh->thigh_left, leg->leg_left, foot->foot_right -->
    <!--
    <body name="thigh_left">
      <joint axis="0 -1 0" name="thigh_left_joint" pos="0 0 1.05" range="-150 0" type="hinge"/>
      <geom fromto="0 0 1.05 0 0 0.6" name="thigh_left_geom" rgba=".7 .3 .6 1" size="0.05" type="capsule"/>
      <body name="leg_left">
        <joint axis="0 -1 0" name="leg_left_joint" pos="0 0 0.6" range="-150 0" type="hinge"/>
        <geom fromto="0 0 0.6 0 0 0.1" name="leg_left_geom" rgba=".7 .3 .6 1" size="0.04" type="capsule"/>
        <body name="foot_left">
          <joint axis="0 -1 0" name="foot_left_joint" pos="0 0 0.1" range="-45 45" type="hinge"/>
          <geom fromto="-0.0 0 0.1 0.2 0 0.1" name="foot_left_geom" rgba=".7 .3 .6 1" size="0.06" type="capsule"/>
        </body>
      </body>
    </body>
    -->
  </worldbody>
    <!--
  <actuator>
    <!-- <motor joint="torso_joint" ctrlrange="-100.0 100.0" isctrllimited="true"/>
    <motor ctrllimited="true" ctrlrange="-1.0 1.0" gear="200" joint="base_joint"/>
    <motor ctrllimited="true" ctrlrange="-1.0 1.0" gear="200" joint="leg_joint"/>
    <!-- <motor joint="finger2_rot" ctrlrange="-20.0 20.0" isctrllimited="true"/>
  </actuator> -->

</mujoco>
